Workbook
Name AU_TZ: #REF!

Sheet 00) Due Dates
B1: Bill | C1: Instatution | D1: Cost | E1: May | F1: June | G1: July | H1: August | I1: September | J1: October | K1: November | L1: December
B2: Subscription - Video | C2: Amazon Priome | D2: -15.04 | E2: 45424 | F2: =EDATE(E2,1) -> 45455 | G2: =EDATE(F2,1) -> 45485 | H2: =EDATE(G2,1) -> 45516 | I2: =EDATE(H2,1) -> 45547 | J2: =EDATE(I2,1) -> 45577 | K2: =EDATE(J2,1) -> 45608 | L2: =EDATE(K2,1) -> 45638
B3: Planet Fitness | C3: Planet Fitness | D3: -10 | E3: 45429 | F3: =EDATE(E3,1) -> 45460 | G3: =EDATE(F3,1) -> 45490 | H3: =EDATE(G3,1) -> 45521 | I3: =EDATE(H3,1) -> 45552 | J3: =EDATE(I3,1) -> 45582 | K3: =EDATE(J3,1) -> 45613 | L3: =EDATE(K3,1) -> 45643
B4: US Cellular | C4: US Cellular | D4: -35 | E4: 45434 | F4: =EDATE(E4,1) -> 45465 | G4: =EDATE(F4,1) -> 45495 | H4: =EDATE(G4,1) -> 45526 | I4: =EDATE(H4,1) -> 45557 | J4: =EDATE(I4,1) -> 45587 | K4: =EDATE(J4,1) -> 45618 | L4: =EDATE(K4,1) -> 45648
B5: WPS (Gas Bill) | C5: WPS | D5: -47 | E5: 45434 | F5: =EDATE(E5,1) -> 45465 | G5: =EDATE(F5,1) -> 45495 | H5: =EDATE(G5,1) -> 45526 | I5: =EDATE(H5,1) -> 45557 | J5: =EDATE(I5,1) -> 45587 | K5: =EDATE(J5,1) -> 45618 | L5: =EDATE(K5,1) -> 45648
B6: Subscription - Video | C6: Crunchyroll | D6: -10.49 | E6: 45436 | F6: =EDATE(E6,1) -> 45467 | G6: =EDATE(F6,1) -> 45497 | H6: =EDATE(G6,1) -> 45528 | I6: =EDATE(H6,1) -> 45559 | J6: =EDATE(I6,1) -> 45589 | K6: =EDATE(J6,1) -> 45620 | L6: =EDATE(K6,1) -> 45650
B7: XFinity | C7: XFinity | D7: -80.75 | E7: 45445 | F7: =EDATE(E7,1) -> 45475 | G7: =EDATE(F7,1) -> 45506 | H7: =EDATE(G7,1) -> 45537 | I7: =EDATE(H7,1) -> 45567 | J7: =EDATE(I7,1) -> 45598 | K7: =EDATE(J7,1) -> 45628
B8: MPU (Electric Bill) | C8: MPU | D8: -75 | E8: 45446 | F8: =EDATE(E8,1) -> 45476 | G8: =EDATE(F8,1) -> 45507 | H8: =EDATE(G8,1) -> 45538 | I8: =EDATE(H8,1) -> 45568 | J8: =EDATE(I8,1) -> 45599 | K8: =EDATE(J8,1) -> 45629
B9: Maintenance | C9: GitHub | D9: -10 | E9: 45446 | F9: =EDATE(E9,1) -> 45476 | G9: =EDATE(F9,1) -> 45507 | H9: =EDATE(G9,1) -> 45538 | I9: =EDATE(H9,1) -> 45568 | J9: =EDATE(I9,1) -> 45599 | K9: =EDATE(J9,1) -> 45629
B10: Car Insurance | C10: Geico | D10: -102.35 | E10: 45451 | F10: =EDATE(E10,1) -> 45481 | G10: =EDATE(F10,1) -> 45512 | H10: =EDATE(G10,1) -> 45543 | I10: =EDATE(H10,1) -> 45573 | J10: =EDATE(I10,1) -> 45604 | K10: =EDATE(J10,1) -> 45634
B11: Renter's Insurance | C11: Assurant | D11: -14.59 | E11: 45451 | F11: =EDATE(E11,1) -> 45481 | G11: =EDATE(F11,1) -> 45512 | H11: =EDATE(G11,1) -> 45543 | I11: =EDATE(H11,1) -> 45573 | J11: =EDATE(I11,1) -> 45604 | K11: =EDATE(J11,1) -> 45634
B13: Bill | C13: Instatution | D13: Cost | E13: May | F13: June | G13: July | H13: August | I13: September | J13: October | K13: November | L13: December
B14: Credit Card | C14: Mission Lane | D14: -25 | E14: 45436 | F14: =EDATE(E14,1) -> 45467 | G14: =EDATE(F14,1) -> 45497 | H14: =EDATE(G14,1) -> 45528 | I14: =EDATE(H14,1) -> 45559 | J14: =EDATE(I14,1) -> 45589 | K14: =EDATE(J14,1) -> 45620 | L14: =EDATE(K14,1) -> 45650
B15: Credit Card | C15: Amazon | D15: -36 | E15: 45437 | F15: =EDATE(E15,1) -> 45468 | G15: =EDATE(F15,1) -> 45498 | H15: =EDATE(G15,1) -> 45529 | I15: =EDATE(H15,1) -> 45560 | J15: =EDATE(I15,1) -> 45590 | K15: =EDATE(J15,1) -> 45621 | L15: =EDATE(K15,1) -> 45651
B16: Rent | C16: Chad Mrotek | D16: -875 | E16: 45444 | F16: =EDATE(E16,1) -> 45474 | G16: =EDATE(F16,1) -> 45505 | H16: =EDATE(G16,1) -> 45536 | I16: =EDATE(H16,1) -> 45566 | J16: =EDATE(I16,1) -> 45597 | K16: =EDATE(J16,1) -> 45627
B17: Rent (Water) | C17: Chad Mrotek | D17: -40 | E17: 45444 | F17: =EDATE(E17,1) -> 45474 | G17: =EDATE(F17,1) -> 45505 | H17: =EDATE(G17,1) -> 45536 | I17: =EDATE(H17,1) -> 45566 | J17: =EDATE(I17,1) -> 45597 | K17: =EDATE(J17,1) -> 45627
B18: Car Payment | C18: Bridgecrest | D18: -531 | E18: 45451 | F18: =EDATE(E18,1) -> 45481 | G18: =EDATE(F18,1) -> 45512 | H18: =EDATE(G18,1) -> 45543 | I18: =EDATE(H18,1) -> 45573 | J18: =EDATE(I18,1) -> 45604 | K18: =EDATE(J18,1) -> 45634
B20: Bill | C20: Instatution | D20: Cost | E20: July | F20: August | G20: September | H20: October | I20: November | J20: December
B21: Medication | C21: Hims | D21: -65 | E21: 45479 | F21: =EDATE(E21,1) -> 45510 | G21: =EDATE(F21,1) -> 45541 | H21: =EDATE(G21,1) -> 45571 | I21: =EDATE(H21,1) -> 45602 | J21: =EDATE(I21,1) -> 45632
B23: Direct Witdrawl Bills
B24: Bill | C24: Cost (BiWeekly) | D24: Remaining Cost | E24: Remaining Payments
B25: MDG | C25: 48.47 | D25: 2076.78 | E25: 99
B26: Above Lending | C26: 86.95 | D26: 5191.76 | E26: 84

Sheet 01) Bill Information
A1: Active | B1: Catagory | C1: Keyword | D1: Bill Type | E1: Last Pay Date | F1: Due Date | G1: Amount
A2: FALSE | B2: Rent | D2: Month Set | F2: 1 | G2: -966.39
A3: TRUE | B3: XFinity | D3: Month Set | E3: 45746 | F3: 2 | G3: -112.83
A4: TRUE | B4: MPU (Electric Bill) | D4: 30 Day | E4: 45746 | F4: 3 | G4: -61.91
A5: TRUE | B5: Car Insurance | D5: Month Set | E5: 45723 | F5: 8 | G5: -112.57
A6: TRUE | B6: Credit Cards | C6: Lowes | D6: Month Set | E6: 45726 | F6: 13 | G6: -200
A7: TRUE | B7: Planet Fitness | D7: Month Set | E7: 45733 | F7: 17 | G7: -10
A8: TRUE | B8: WPS (Gas Bill) | D8: 30 Day | E8: 45727 | F8: 20 | G8: -47
A9: TRUE | B9: Credit Cards | C9: Mission Lane | D9: Month Set | E9: 45726 | F9: 24 | G9: -50
A10: TRUE | B10: US Cellular | D10: 30 Day | E10: 45723 | F10: 25 | G10: -92.78
A11: TRUE | B11: Credit Cards | C11: Amazon | D11: Month Set | E11: 45726 | F11: 25 | G11: -50
A12: FALSE | B12: Credit Cards | C12: Care Credit | D12: Month Set | F12: 25 | G12: 0
A13: TRUE | B13: Car Payment | D13: Month Set | E13: 45726 | F13: 28 | G13: -471.27
A14: FALSE | B14: Renter's Insurance | D14: Month Set | G14: 0

Sheet Budget 2025
A1: Bill | B1: Date | C1: Payment
A2: Income: Paycheck | B2: 45667 | C2: 1906.37
A3: Above Lending | B3: 45667 | C3: -86.95
A4: Car Payment | B4: 45667 | C4: -471.27
A5: Credit Cards | B5: 45667 | C5: -200
A6: Credit Cards | B6: 45667 | C6: -50
A7: US Cellular | B7: 45667 | C7: -91.59
A8: Planet Fitness | B8: 45667 | C8: -10
A9: Income: Paycheck | B9: 45681 | C9: 1906.37
A10: Above Lending | B10: 45681 | C10: -86.95
A11: Car Payment | B11: 45681 | C11: -471.27
A12: Credit Cards | B12: 45681 | C12: -200
A13: Credit Cards | B13: 45681 | C13: -50
... A202: Car Payment | B202: 46042 | C202: -471.27

Sheet 01.5) Debt
C1: Updated Date: | D1: 45710
A2: Column 1 | B2: Debt | C2: Amount | D2: Montly Payment | E2: Web Link | F2: Ref. | G2: Left | H2: Due | I2: Total | J2: Frequency | K2: Term | L2: Remaining | M2: First | N2: Final | O2: APR
A3: TRUE | B3: MDG | C3: 1859.79 | D3: =48.47*2 -> 96.94 | E3: MDG | G3: 80 | H3: 48.47 | I3: 2107.35 | J3: Bi-Weekly | K3: =IF(J3="Bi-Weekly", DATEDIF(M3, EDATE($D$1, G3/2), "M") / 12, IF(J3="Monthly", DATEDIF(M3, EDATE($D$1, G3), "M") / 12, "Invalid Frequency")) -> 4.5833333 | L3: 1859.79 | M3: 45229 | N3: =EDATE(M3, K3 * 12) -> 46903 | O3: 0.273
A4: TRUE | B4: Above Lending | C4: 4193.08 | D4: =86.95*2 -> 173.9 | E4: Above Lending | G4: 63 | H4: 86.95 | I4: 6186.15 | J4: Bi-Weekly | K4: =IF(J4="Bi-Weekly", DATEDIF(M4, EDATE($D$1, G4/2), "M") / 12, IF(J4="Monthly", DATEDIF(M4, EDATE($D$1, G4), "M") / 12, "Invalid Frequency")) -> 4.9166667 | L4: 4193.08 | M4: 44839 | N4: =EDATE(M4, K4 * 12) -> 46635 | O4: 0.254417
A5: FALSE | B5: Car Loan | C5: 24494.11 | D5: 471.27 | E5: Genisys | G5: 67 | H5: 471.27 | I5: 26622.13 | J5: Monthly | K5: =IF(J5="Bi-Weekly", DATEDIF(M5, EDATE($D$1, G5/2), "M") / 12, IF(J5="Monthly", DATEDIF(M5, EDATE($D$1, G5), "M") / 12, "Invalid Frequency")) -> 6.0833333 | L5: 24494.11 | M5: 45513 | N5: =EDATE(M5, K5 * 12) -> 47735 | O5: 0.0799
A6: FALSE | B6: Amazon Credit Card | C6: 774.82 | D6: 100 | E6: Amazon | J6: Monthly
A7: TRUE | B7: Mission Lane Credit Card | C7: 2548.82 | D7: 200 | E7: Mission Lane | J7: Monthly
A8: FALSE | B8: Lowes (Washer / Dryer) | C8: 369.31 | D8: 194.7 | E8: Lowes (Loan) | J8: Monthly
A9: FALSE | B9: Lowes Credit Card | C9: 1054 | D9: 194.7 | E9: Lowes (Credit) | J9: Monthly
A10: FALSE | B10: Affirm # 1 | C10: =138.67-6.3 -> 132.37 | D10: 0 | E10: Affirm 1 | J10: Monthly
A11: FALSE | B11: Affirm # 2 | C11: =242.2-11.01 -> 231.19 | D11: 0 | E11: Affirm 2 | J11: Monthly
A12: FALSE | B12: Affirm # 3 | C12: =566.65-23.61-23.61 -> 519.43 | D12: 0 | E12: Affirm 3 | J12: Monthly
A13: FALSE | B13: Affirm # 4 | C13: =1129.34-47.06-47.06 -> 1035.22 | D13: 0 | E13: Affirm 4 | J13: Monthly
A14: FALSE | B14: Affirm # 5 | C14: =1136.36-47.37-47.37 -> 1041.62 | D14: 0 | E14: Affirm 5 | J14: Monthly
A15: FALSE | B15: Aurora Collection 1 | C15: 515 | D15: 0 | E15: EvokePay | F15: 12634667 | J15: Monthly
A16: FALSE | B16: Aurora Collection 2 | C16: 1910 | D16: 0 | E16: Call 1-800-215-8756 | F16: 11946574 | J16: Monthly
A17: FALSE | B17: Milestone Credit Card | C17: 1085.49 | D17: 0 | E17: Credit Corp | F17: 32602628 | J17: Monthly
C19: Total Amount | D19: Total Monthly Payment
C20: =IFERROR(__xludf.DUMMYFUNCTION("IF(COUNTIF(A3:A17, TRUE) = 0, 0, SUM(FILTER(C3:C17, A3:A17 = TRUE))) "),8601.69) -> 8601.69 | D20: =IFERROR(__xludf.DUMMYFUNCTION("IF(COUNTIF(A3:A17, TRUE) = 0, 0, SUM(FILTER(D3:D17, A3:A17 = TRUE))) "),470.84000000000003) -> 470.84

Sheet 02) 2023 Shopping List
B2: Tax | C2: Item | D2: Isle | E2: Category | F2: Amount | G2: Cost of One | H2: Total Cost
B3: FALSE | C3: Milk | D3: A-23 | E3: Groceries | F3: 2 | G3: 2.66 | H3: =IF( B3 = TRUE ,(G3*F3)*0.05+(G3*F3) , G3*F3 ) -> 5.32
B4: TRUE | C4: Toilet Bowl Cleaner | D4: J-11 | E4: Bathroom | F4: 1 | G4: 5.18 | H4: =IF( B4 = TRUE ,(G4*F4)*0.05+(G4*F4) , G4*F4 ) -> 5.439
B5: TRUE | C5: Hand Soap | D5: G-16 | E5: Bathroom | F5: 2 | G5: 2.47 | H5: =IF( B5 = TRUE ,(G5*F5)*0.05+(G5*F5) , G5*F5 ) -> 5.187
B6: TRUE | C6: Toilet Paper | D6: J-07 | E6: Bathroom | F6: 1 | G6: 6.98 | H6: =IF( B6 = TRUE ,(G6*F6)*0.05+(G6*F6) , G6*F6 ) -> 7.329
B7: FALSE | C7: Pop Tarts | D7: A-08 | E7: Groceries | F7: 1 | G7: 4.47 | H7: =IF( B7 = TRUE ,(G7*F7)*0.05+(G7*F7) , G7*F7 ) -> 4.47
B8: FALSE | C8: Zebra Cakes | D8: A-06 | E8: Groceries (Lunch) | F8: 4 | G8: 2.68 | H8: =IF( B8 = TRUE ,(G8*F8)*0.05+(G8*F8) , G8*F8 ) -> 10.72
B9: FALSE | C9: Oreos | D9: A-18 | E9: Groceries | F9: 1 | G9: 4.58 | H9: =IF( B9 = TRUE ,(G9*F9)*0.05+(G9*F9) , G9*F9 ) -> 4.58
B10: FALSE | C10: Soda | D10: A-20 | E10: Groceries | F10: 4 | G10: 3.88 | H10: =IF( B10 = TRUE ,(G10*F10)*0.05+(G10*F10) , G10*F10 ) -> 15.52
B11: FALSE | C11: Pizza | D11: A-04 | E11: Groceries | F11: 2 | G11: 3.98 | H11: =IF( B11 = TRUE ,(G11*F11)*0.05+(G11*F11) , G11*F11 ) -> 7.96
B12: FALSE | C12: Nutter Butters | D12: A-18 | E12: Groceries | F12: 1 | G12: 4.68 | H12: =IF( B12 = TRUE ,(G12*F12)*0.05+(G12*F12) , G12*F12 ) -> 4.68
B13: FALSE | G13: 0 | H13: =IF( B13 = TRUE ,(G13*F13)*0.05+(G13*F13) , G13*F13 ) -> 0
B14: FALSE | G14: 0 | H14: =IF( B14 = TRUE ,(G14*F14)*0.05+(G14*F14) , G14*F14 ) -> 0
B15: FALSE | G15: 0 | H15: =IF( B15 = TRUE ,(G15*F15)*0.05+(G15*F15) , G15*F15 ) -> 0
B16: FALSE | G16: 0 | H16: =IF( B16 = TRUE ,(G16*F16)*0.05+(G16*F16) , G16*F16 ) -> 0
B17: FALSE | G17: 0 | H17: =IF( B17 = TRUE ,(G17*F17)*0.05+(G17*F17) , G17*F17 ) -> 0
B18: FALSE | C18: Hydroxizine | D18: CVS | E18: Medical | F18: 1 | G18: 10 | H18: =IF( B18 = TRUE ,(G18*F18)*0.05+(G18*F18) , G18*F18 ) -> 10
B19: FALSE | C19: Mission Lane Credit Card | F19: 1 | G19: -287.08 | H19: =IF( B19 = TRUE ,(G19*F19)*0.05+(G19*F19) , G19*F19 ) -> -287.08
B20: FALSE | G20: 0 | H20: =IF( B20 = TRUE ,(G20*F20)*0.05+(G20*F20) , G20*F20 ) -> 0
B21: FALSE | G21: 0 | H21: =IF( B21 = TRUE ,(G21*F21)*0.05+(G21*F21) , G21*F21 ) -> 0
B22: FALSE | G22: 0 | H22: =IF( B22 = TRUE ,(G22*F22)*0.05+(G22*F22) , G22*F22 ) -> 0
B23: FALSE | G23: 0 | H23: =IF( B23 = TRUE ,(G23*F23)*0.05+(G23*F23) , G23*F23 ) -> 0
B24: FALSE | G24: 0 | H24: =IF( B24 = TRUE ,(G24*F24)*0.05+(G24*F24) , G24*F24 ) -> 0
B25: FALSE | G25: 0 | H25: =IF( B25 = TRUE ,(G25*F25)*0.05+(G25*F25) , G25*F25 ) -> 0
B26: FALSE | G26: 0 | H26: =IF( B26 = TRUE ,(G26*F26)*0.05+(G26*F26) , G26*F26 ) -> 0
B27: FALSE | G27: 0 | H27: =IF( B27 = TRUE ,(G27*F27)*0.05+(G27*F27) , G27*F27 ) -> 0
B28: FALSE | G28: 0 | H28: =IF( B28 = TRUE ,(G28*F28)*0.05+(G28*F28) , G28*F28 ) -> 0
B29: FALSE | G29: 0 | H29: =IF( B29 = TRUE ,(G29*F29)*0.05+(G29*F29) , G29*F29 ) -> 0
B30: FALSE | G30: 0 | H30: =IF( B30 = TRUE ,(G30*F30)*0.05+(G30*F30) , G30*F30 ) -> 0
B31: FALSE | G31: 0 | H31: =IF( B31 = TRUE ,(G31*F31)*0.05+(G31*F31) , G31*F31 ) -> 0
... B52: FALSE | G52: 0 | H52: =IF( B52 = TRUE ,(G52*F52)*0.05+(G52*F52) , G52*F52 ) -> 0
C53: Total Cost: | H53: =sum(H3:H52) -> -205.875
B54: Remaining Balance: | H54: ='11) 2023 BudgetBill Breakdown'!H273-H53 -> 220.225

Sheet 03) Current YTD Report
J1: DROPDOWN
B2: Income | C2: 2024 YTD Amount | G2: US Cellular | H2: =-I$2/C$33 -> 0.027968977 | I2: =SUMIF('01) BudgetBill Breakdown'!B$1:B37,J$6, '01) BudgetBill Breakdown'!G$1:G37) -> -2833.84 | J2: Income: Paycheck
B3: =J2 -> Income: Paycheck | C3: =SUMIF('01) BudgetBill Breakdown'!B1:B37,B3, '01) BudgetBill Breakdown'!G1:G37) -> 96053.7 | G3: =J$7 -> Rent | H3: =-I$3/C$33 -> 0.26130195 | I3: =SUMIF('01) BudgetBill Breakdown'!B$1:B37,"Rent", '01) BudgetBill Breakdown'!G$1:G37) -> -26475.33 | J3: Income: Lottery
B4: =J4 -> Income: Tax Return | C4: =SUMIF('01) BudgetBill Breakdown'!B$1:B37,B4, '01) BudgetBill Breakdown'!G$1:G37) -> 3973 | G4: ='08) Drop Down Menus'!$A$2 -> Groceries | H4: =-I$4/C$33 -> 0.13088789 | I4: =SUMIF('01) BudgetBill Breakdown'!B$1:B37,J$8, '01) BudgetBill Breakdown'!G$1:G37) -> -13261.67 | J4: Income: Tax Return
B5: =J5 -> Income: Other | C5: =SUMIF('01) BudgetBill Breakdown'!B$1:B37,B5, '01) BudgetBill Breakdown'!G$1:G37) -> 1294.13 | G5: ='08) Drop Down Menus'!$A$3 -> Cigarettes | H5: =-I$5/C$33 -> 0.031539813 | I5: =SUMIF('01) BudgetBill Breakdown'!B$1:B37,J$9, '01) BudgetBill Breakdown'!G$1:G37) -> -3195.64 | J5: Income: Other
G6: ='08) Drop Down Menus'!$A$4 -> Gas | H6: =-I$6/C$33 -> 0.011050048 | I6: =SUMIF('01) BudgetBill Breakdown'!B$1:B37,J$10, '01) BudgetBill Breakdown'!G$1:G37) -> -1119.6 | J6: US Cellular
B7: Expence | C7: YTD Cost | D7: Percentile | E7: Monthly Avg. | G7: ='08) Drop Down Menus'!$A$5 -> Entertainment | H7: =-I$7/C$33 -> 0.051025145 | I7: =SUMIF('01) BudgetBill Breakdown'!B$1:B37,J$11, '01) BudgetBill Breakdown'!G$1:G37) -> -5169.91 | J7: Rent
B8: =G$3 -> Rent | C8: =I$3-935 -> -27410.33 | D8: =H$3 -> 0.26130195 | E8: =C8/H$26 -> -8092.5736 | G8: ='08) Drop Down Menus'!$A$6 -> Medical | H8: =-I$8/C$33 -> 0.012135116 | I8: =SUMIF('01) BudgetBill Breakdown'!B$1:B37,J$12, '01) BudgetBill Breakdown'!G$1:G37) -> -1229.54 | J8: Groceries
B9: =G$4 -> Groceries | C9: =I$4 -> -13261.67 | D9: =H$4 -> 0.13088789 | E9: =C9/H$26 -> -3915.3502 | G9: ='08) Drop Down Menus'!$A$7 -> Vehicle | H9: =-I$9/C$33 -> 0.0078796236 | I9: =SUMIF('01) BudgetBill Breakdown'!B$1:B37,J$13, '01) BudgetBill Breakdown'!G$1:G37) -> -798.37 | J9: Cigarettes
B10: =G$13 -> Car Payment | C10: =I$13-300 -> -12918.59 | D10: =H$13 -> 0.12454093 | E10: =C10/H$26 -> -3814.0599 | G10: ='08) Drop Down Menus'!$A$8 -> Maintenance | H10: =-I$10/C$33 -> 0.024703509 | I10: =SUMIF('01) BudgetBill Breakdown'!B$1:B37,J$14, '01) BudgetBill Breakdown'!G$1:G37) -> -2502.98 | J10: Gas
B11: =G$2 -> US Cellular | C11: =I$2 -> -2833.84 | D11: =H$2 -> 0.027968977 | E11: =C11/H$26 -> -836.65752 | G11: Above Lending | H11: =-I$11/C$33 -> 0.048915411 | I11: =SUMIF('01) BudgetBill Breakdown'!B$1:B37,J$15, '01) BudgetBill Breakdown'!G$1:G37) -> -4956.15 | J11: Entertainment
B12: =G$11 -> Above Lending | C12: =I$11 -> -4956.15 | D12: =H$11 -> 0.048915411 | E12: =C12/H$26 -> -1463.2443 | G12: Planet Fitness | H12: =-I$12/C$33 -> 0.0030497184 | I12: =SUMIF('01) BudgetBill Breakdown'!B$1:B37,J$16, '01) BudgetBill Breakdown'!G$1:G37) -> -309 | J12: Medical
B13: =G$5 -> Cigarettes | C13: =I$5 -> -3195.64 | D13: =H$5 -> 0.031539813 | E13: =C13/H$26 -> -943.47467 | G13: Car Payment | H13: =-I$13/C$33 -> 0.12454093 | I13: =SUMIF('01) BudgetBill Breakdown'!B$1:B37,J$17, '01) BudgetBill Breakdown'!G$1:G37) -> -12618.59 | J13: Vehicle
B14: =G$16 -> XFinity | C14: =I$16 -> -2601.07 | D14: =H$16 -> 0.025671622 | E14: =C14/H$26 -> -767.93495 | G14: WPS (Gas Bill) | H14: =-I$14/C$33 -> 0.014091673 | I14: =SUMIF('01) BudgetBill Breakdown'!B$1:B37,J$18, '01) BudgetBill Breakdown'!G$1:G37) -> -1427.78 | J14: Maintenance
B15: =G$14 -> WPS (Gas Bill) | C15: =I$14 -> -1427.78 | D15: =H$14 -> 0.014091673 | E15: =C15/H$26 -> -421.53505 | G15: Credit Cards | H15: =-I$15/C$33 -> 0.10297132 | I15: =SUMIF('01) BudgetBill Breakdown'!B$1:B37,J$19, '01) BudgetBill Breakdown'!G$1:G37) -> -10433.14 | J15: Above Lending
B16: =G$7 -> Entertainment | C16: =I$7 -> -5169.91 | D16: =H$7 -> 0.051025145 | E16: =C16/H$26 -> -1526.3544 | G16: XFinity | H16: =-I$16/C$33 -> 0.025671622 | I16: =SUMIF('01) BudgetBill Breakdown'!B$1:B37,J$20, '01) BudgetBill Breakdown'!G$1:G37) -> -2601.07 | J16: Planet Fitness
B17: =G$10 -> Maintenance | C17: =I$10 -> -2502.98 | D17: =H$10 -> 0.024703509 | E17: =C17/H$26 -> -738.97505 | G17: Car Insurance | H17: =-I$17/C$33 -> 0.028165383 | I17: =SUMIF('01) BudgetBill Breakdown'!B$1:B37,J$21, '01) BudgetBill Breakdown'!G$1:G37) -> -2853.74 | J17: Car Payment
B18: =G$15 -> Credit Cards | C18: =I$15 -> -10433.14 | D18: =H$15 -> 0.10297132 | E18: =C18/H$26 -> -3080.2604 | G18: Renter's Insurance | H18: =-I$18/C$33 -> 0.0016277995 | I18: =SUMIF('01) BudgetBill Breakdown'!B$1:B37,J$22, '01) BudgetBill Breakdown'!G$1:G37) -> -164.93 | J18: WPS (Gas Bill)
B19: =G$17 -> Car Insurance | C19: =I$17 -> -2853.74 | D19: =H$17 -> 0.028165383 | E19: =C19/H$26 -> -842.53276 | G19: Subscription - Video | H19: =-I$19/C$33 -> 0.0063419338 | I19: =SUMIF('01) BudgetBill Breakdown'!B$1:B37,J$23, '01) BudgetBill Breakdown'!G$1:G37) -> -642.57 | J19: Credit Cards
B20: =G$9 -> Vehicle | C20: =I$9 -> -798.37 | D20: =H$9 -> 0.0078796236 | E20: =C20/H$26 -> -235.70924 | G20: Subscription - Game | H20: =-I$20/C$33 -> 0.0013532262 | I20: =SUMIF('01) BudgetBill Breakdown'!B$1:B37,J$24, '01) BudgetBill Breakdown'!G$1:G37) -> -137.11 | J20: XFinity
B21: =G$21 -> MPU (Electric Bill) | C21: =I$21 -> -2424.41 | D21: =H$21 -> 0.023928051 | E21: =C21/H$26 -> -715.77819 | G21: MPU (Electric Bill) | H21: =-I$21/C$33 -> 0.023928051 | I21: =SUMIF('01) BudgetBill Breakdown'!B$1:B37,J$25, '01) BudgetBill Breakdown'!G$1:G37) -> -2424.41 | J21: Car Insurance
B22: =G$22 -> Debt | C22: =I$22 -> -4471.64 | D22: =H$22 -> 0.044133472 | E22: =C22/H$26 -> -1320.1985 | G22: Debt | H22: =-I$22/C$33 -> 0.044133472 | I22: =SUMIF('01) BudgetBill Breakdown'!B$1:B37,J$26, '01) BudgetBill Breakdown'!G$1:G37) -> -4471.64 | J22: Renter's Insurance
B23: =G$6 -> Gas | C23: =I$6 -> -1119.6 | D23: =H$6 -> 0.011050048 | E23: =C23/H$26 -> -330.54857 | G23: Holiday Gifts | H23: =-I$23/C$33 -> 0.0043158944 | I23: =SUMIF('01) BudgetBill Breakdown'!B$1:B37,J$27, '01) BudgetBill Breakdown'!G$1:G37) -> -437.29 | J23: Subscription - Video
B24: =G$8 -> Medical | C24: =I$8 -> -1229.54 | D24: =H$8 -> 0.012135116 | E24: =C24/H$26 -> -363.00705 | G24: Haircut | H24: =-I$24/C$33 -> 0.0034566436 | I24: =SUMIF('01) BudgetBill Breakdown'!B$1:B37,J$28, '01) BudgetBill Breakdown'!G$1:G37) -> -350.23 | J24: Subscription - Game
B25: =G$19 -> Subscription - Video | C25: =I$19 -> -642.57 | D25: =H$19 -> 0.0063419338 | E25: =C25/H$26 -> -189.71114 | J25: MPU (Electric Bill)
B26: =G$18 -> Renter's Insurance | C26: =I$18 -> -164.93 | D26: =H$18 -> 0.0016277995 | E26: =C26/H$26 -> -48.693619 | G26: Month + Day | H26: =H27+(H28/H30) -> 3.3870968 | J26: Debt
B27: =G$12 -> Planet Fitness | C27: =I$12 -> -309 | D27: =H$12 -> 0.0030497184 | E27: =C27/H$26 -> -91.228571 | G27: Current Month | H27: =Month(NOW()) -> 3 | J27: Holiday Gifts
B28: Holiday Gifts | C28: =I$23 -> -437.29 | D28: =H$23 -> 0.0043158944 | E28: =C28/H$26 -> -129.10467 | G28: Current Day | H28: =DAY(NOW()) -> 12 | J28: Haircut
B29: Haircut | C29: =I$24 -> -350.23 | D29: =H$24 -> 0.0034566436 | E29: =C29/H$26 -> -103.40124
B30: =G$20 -> Subscription - Game | C30: =I$20 -> -137.11 | D30: =H$20 -> 0.0013532262 | E30: =C30/H$26 -> -40.480095 | G30: Last Day | H30: =DAY(EOMONTH(TODAY(),0)) -> 31
G31: Year | H31: =YEAR(TODAY()) -> 2026
B32: YTD Total Spent | C32: =sum(I2:I22) -> -99627.01
B33: YTD Total Earned | C33: =sum(C3:C5) -> 101320.83
B34: Difference | C34: =C33+C32 -> 1693.82
B35: % Profit | C35: =C34/C33 -> 0.016717392
B36: Possible Monthly Savings | C36: =-(E11+E9+E23+30+200) -> 4852.5563
B37: * Paycheck YTD is Gross not Net | E37: ="Report Date : " & $H$27 & "/" & $H$28 & "/" & $H$31 -> Report Date : 3/12/2026

Sheet 04) 2023 Rent Schedule
A1: Date | B1: Amount | C1: Description | D1: Extra
A2: 44741 | B2: 100 | C2: Cash Down/July Rent | E2: Total Rent Paid : | F2: =sum(B2:B22)-F3-F4 -> 8950
A3: 44743 | B3: 795 | C3: Remaining July Rent | E3: Total Water Paid : | F3: =29.88+28.8+34.81+24.81+42.62+28.1+24.54+52.52 -> 266.08
A4: 44757 | B4: 671.25 | C4: 1st Half August | D4: 1/4 Sec. Dep ($223.75) | E4: Security Deposit : | F4: 895
A5: 44774 | B5: 671.25 | C5: 2nd Half August | D5: 1/4 Sec. Dep ($223.75)
A6: 44785 | B6: 671.25 | C6: 1st Half September | D6: 1/4 Sec. Dep ($223.75)
A7: 44799 | B7: 671.25 | C7: 2nd Half September | D7: 1/4 Sec. Dep ($223.75)
A8: 44813 | B8: 477.38 | C8: 1st Half October | D8: July Water ($29.88)
A9: 44830 | B9: 447.5 | C9: 2nd Half October | D9: Only Rent
A10: 44841 | B10: 447.5 | C10: 1st Half November | D10: Only Rent
A11: 44855 | B11: 476.3 | C11: 2nd Half November | D11: August Water ($28.80)
A12: 44869 | B12: 482.31 | C12: 1st Half December | D12: September Water ($34.81)
A13: 44883 | B13: 447.5 | C13: 2nd Half December | D13: Only Rent
A14: 44897 | B14: 472.31 | C14: 1st Half January | D14: October Water ($24.81)
A15: 44911 | B15: 447.5 | C15: 2nd Half January | D15: Only Rent
A16: 44929 | B16: 42.62 | C16: Water Only | D16: November Water ($42.62)
A17: 44944 | B17: 0
A18: 44953 | B18: 923.1 | C18: February Rent | D18: December Water ($28.10)
A19: 44967 | B19: 0
A20: 44981 | B20: 919.54 | C20: March Rent | D20: January Water ($24.54)
A21: 44995
A22: 45009 | B22: =447.5*2+52.52 -> 947.52 | C22: April Rent | D22: February Water ($52.52)
A23: 45023
A24: 45037 | B24: =447.5*2 -> 895 | C24: May Rent | D24: March Water
A25: 45051 | B25: 447.5 | C25: 1st Half June | D25: Only Rent
A26: 45065 | C26: 2nd Half June | D26: April Water
A27: 45079 | B27: 447.5 | C27: 1st Half July | D27: Only Rent
A28: 45093 | C28: 2nd Half July | D28: May Water
A29: End of 1 Year Lease
A30: 45107 | B30: 0 | C30: NOTHING | D30: NOTHING
A31: 45121 | C31: 1st Half August | D31: June Water
A32: 45135 | B32: 447.5 | C32: 2nd Half August | D32: Only Rent
A33: 45149 | C33: 1st Half September | D33: July Water
A34: 45163 | B34: 447.5 | C34: 2nd Half September | D34: Only Rent
A35: 45177 | C35: 1st Half October | D35: August Water
A36: 45191 | B36: 447.5 | C36: 2nd Half October | D36: Only Rent
A37: 45205 | C37: 1st Half November | D37: September Water
A38: 45219 | B38: 447.5 | C38: 2nd Half November | D38: Only Rent
A39: 45233 | C39: 1st Half December | D39: October Water
A40: 45247 | B40: 447.5 | C40: 2nd Half December | D40: Only Rent
...

Sheet 05) Paycheck Calculator
C2: Rate | D2: Hours | E2: Earned | G2: Taxes | I2: % | L2: Week 1
B3: Normal Time | C3: 18.03 | D3: 80 | E3: =C3*D3 -> 1442.4 | G3: Federal | H3: =E7*I3 -> 159.05278 | I3: 0.063918123 | L3: Sunday | M3: Monday | N3: Tuesday | O3: Wednesday | P3: Thursday | Q3: Friday | R3: Saturday
B4: Shift Premium | C4: 3 | D4: =D3 -> 80 | E4: =C4*D4 -> 240 | G4: Social Security | H4: =E7*I4 -> 157.66469 | I4: 0.063360292 | K4: Date: | L4: 45368 | M4: =L4+1 -> 45369 | N4: =M4+1 -> 45370 | O4: =N4+1 -> 45371 | P4: =O4+1 -> 45372 | Q4: =P4+1 -> 45373 | R4: =Q4+1 -> 45374
B5: Overtime | C5: =C3*1.5+C4 -> 30.045 | D5: =L7+L14 -> 32 | E5: =C5*D5 -> 961.44 | G5: Medicare | H5: =E7*I5 -> 36.880967 | I5: 0.014821257 | K5: Hours: | L5: 11 | M5: =8.5+2.5 -> 11 | N5: 12 | O5: 12 | P5: 12 | Q5: =8.5+3 -> 11.5 | R5: 0
B6: Total Earned : | E6: =SUM(E3:E5) -> 2643.84 | G6: WI State | H6: =E7*I6 -> 88.626139 | I6: 0.035615953 | K6: Total Hours: | L6: =L5 -> 11 | M6: =L6+M5 -> 22 | N6: =M6+N5 -> 34 | O6: =N6+O5 -> 46 | P6: =O6+P5 -> 58 | Q6: =P6+Q5 -> 69.5 | R6: =Q6+R5 -> 69.5
B7: Taxable Income : | E7: =E6-H18 -> 2488.3832 | G7: Total Taxes | H7: =SUM(H3:H6) -> 442.22457 | K7: Total O.T.: | L7: =MAX(0,sum(L5:R5)-40) -> 29.5
B9: Tax Rate | G9: Benefits | L9: Week 2
B10: =H7/E7 -> 0.17771562 | G10: Add Vision | H10: 3.35 | L10: Sunday | M10: Monday | N10: Tuesday | O10: Wednesday | P10: Thursday | Q10: Friday | R10: Saturday
G11: Flex | H11: 19.23 | K11: Date: | L11: =R4+1 -> 45375 | M11: =L11+1 -> 45376 | N11: =M11+1 -> 45377 | O11: =N11+1 -> 45378 | P11: =O11+1 -> 45379 | Q11: =P11+1 -> 45380 | R11: =Q11+1 -> 45381
B12: Take Home | G12: Life & Disability | H12: 2 | K12: Hours: | L12: 0 | M12: 8.5 | N12: 8.5 | O12: 8.5 | P12: 8.5 | Q12: 8.5 | R12: 0
B13: =E6-(E7*B10)-H18-H16 -> 2036.9686 | G13: Seos 4000 | H13: 75 | K13: Total Hours: | L13: =R6+L12 -> 69.5 | M13: =L13+M12 -> 78 | N13: =M13+N12 -> 86.5 | O13: =N13+O12 -> 95 | P13: =O13+P12 -> 103.5 | Q13: =P13+Q12 -> 112 | R13: =Q13+R12 -> 112
G14: Sing Dental | H14: 3 | K14: Total O.T.: | L14: =MAX(0,sum(L12:R12)-40) -> 2.5
G15: 401K | H15: =E6*2% -> 52.8768
G16: Additional Life | H16: 9.19
G17: Total Benefits | H17: =sum(H10:H16) -> 164.6468
G18: Non Tax Benefits | H18: =sum(H10:I15) -> 155.4568
G19: Benefit % | H19: =1-(E7/E6) -> 0.058799625

Sheet 06) Med Counter
B1: 45067
B2: Medication | C2: Amount | D2: Per Day | E2: Days Left | F2: Months Left | G2: Refill Date
B3: Venlafaxine | C3: 41 | D3: 1 | E3: =C3/D3 -> 41 | F3: =E3/31 -> 1.3225806 | G3: =B$1+E3-5 -> 45103
B4: Vyvanse | C4: 15 | D4: 1 | E4: =C4/D4 -> 15 | F4: =E4/31 -> 0.48387097 | G4: =B$1+E4-5 -> 45077
B5: Hydroxyzine | C5: =27+14 -> 41 | D5: 2 | E5: =C5/D5 -> 20.5 | F5: =E5/31 -> 0.66129032 | G5: =B$1+E5-5 -> 45082.5
B6: Prazosin | C6: 262 | D6: 2 | E6: =C6/D6 -> 131 | F6: =E6/31 -> 4.2258065 | G6: =B$1+E6-5 -> 45193
B7: Omeprazole | C7: 19 | D7: 1 | E7: =C7/D7 -> 19 | F7: =E7/31 -> 0.61290323 | G7: =B$1+E7-5 -> 45081
B8: Diphenhydramine | C8: 98 | D8: 2 | E8: =C8/D8 -> 49 | F8: =E8/31 -> 1.5806452 | G8: =B$1+E8-5 -> 45111

Sheet 06) W@H Timecard
B2: MTM Application Time Card - John Koll
B3: Date Range - 12/04/2023 to 12/10/2023
B5: Date | C5: Start | D5: Stop | E5: Worked On | F5: Total
B6: 45264 | C6: 0.83333333 | D6: 0.91666667 | E6: Started: Main Screen UI Design & Coding | F6: =D6-C6 -> 0.083333333
B7: 45265 | C7: 0.58333333 | D7: 0.95833333 | E7: Started: Waitlist Component Design & Coding Continued: Main Screen UI Design & Coding | F7: =D7-C7 -> 0.375
B8: 45266 | C8: 0.58333333 | D8: 0.83333333 | E8: Started: Waitlist Request-Bar Component Design and Coding Started: Waitlist Side-Bar Component Design and Coding Continued: Main Screen UI Design and Coding Continued: Waitlist Component Design and Coding | F8: =D8-C8 -> 0.25
B9: 45267 | C9: 0.66666667 | D9: 0.95833333 | E9: Started: Waitlist Side-Bar Component Design and Coding Continued: Waitlist Component Design and Coding Created: This Spreadsheet | F9: =D9-C9 -> 0.29166667
B10: 45269 | C10: 0.66666667 | D10: 0.85416667 | E10: Continued: Coding Waitlist viewer component. | F10: =D10-C10 -> 0.1875
F11: =D11-C11 -> 0
F12: =D12-C12 -> 0
F13: =D13-C13 -> 0
F14: =D14-C14 -> 0
F15: =D15-C15 -> 0
F16: =D16-C16 -> 0
F17: =D17-C17 -> 0
F18: =D18-C18 -> 0
B20: Total time worked: | C20: =SUM(F6:F18) -> 1.1875

Sheet 07) Car Loan Calculator
B2: Period | C2: Date | D2: Monthly Payment | E2: Interest Payment | F2: Principal Payment | G2: Loan Balance | I2: Principal amount | J2: Interest Rate
B3: 0 | C3: =J5 -> 44273 | D3: 0 | E3: 0 | F3: 0 | G3: =I3 -> 13424.38 | I3: 13424.38 | J3: 0.164
B4: =B3+1 -> 1 | C4: =DATE(YEAR(C3),MONTH(C3)+1,Day(C3)) -> 44304 | D4: -298.96 | E4: =IPMT($J$3/12, B4, $I$5*12,$I$3) -> -183.46653 | F4: =D4-E4 -> -115.49347 | G4: =F4+G3 -> 13308.887 | I4: Term (in years) | J4: Starting Date
B5: =B4+1 -> 2 | C5: =DATE(YEAR(C4),MONTH(C4)+1,Day(C4)) -> 44334 | D5: -298.96 | E5: =IPMT($J$3/12, B5, $I$5*12,$I$3) -> -181.95366 | F5: =D5-E5 -> -117.00634 | G5: =F5+G4 -> 13191.88 | I5: 6 | J5: 44273
B6: =B5+1 -> 3 | C6: =DATE(YEAR(C5),MONTH(C5)+1,Day(C5)) -> 44365 | D6: -298.96 | E6: =IPMT($J$3/12, B6, $I$5*12,$I$3) -> -180.42012 | F6: =D6-E6 -> -118.53988 | G6: =F6+G5 -> 13073.34 | I6: Pay More
B7: =B6+1 -> 4 | C7: =DATE(YEAR(C6),MONTH(C6)+1,Day(C6)) -> 44395 | D7: -298.96 | E7: =IPMT($J$3/12, B7, $I$5*12,$I$3) -> -178.86562 | F7: =D7-E7 -> -120.09438 | G7: =F7+G6 -> 12953.246 | I7: 0
B8: =B7+1 -> 5 | C8: =DATE(YEAR(C7),MONTH(C7)+1,Day(C7)) -> 44426 | D8: -298.96 | E8: =IPMT($J$3/12, B8, $I$5*12,$I$3) -> -177.28988 | F8: =D8-E8 -> -121.67012 | G8: =F8+G7 -> 12831.576
B9: =B8+1 -> 6 | C9: =DATE(YEAR(C8),MONTH(C8)+1,Day(C8)) -> 44457 | D9: -298.96 | E9: =IPMT($J$3/12, B9, $I$5*12,$I$3) -> -175.6926 | F9: =D9-E9 -> -123.2674 | G9: =F9+G8 -> 12708.308 | I9: Last Pay Date | J9: 46464
B10: =B9+1 -> 7 | C10: =DATE(YEAR(C9),MONTH(C9)+1,Day(C9)) -> 44487 | D10: -298.96 | E10: =IPMT($J$3/12, B10, $I$5*12,$I$3) -> -174.07349 | F10: =D10-E10 -> -124.88651 | G10: =F10+G9 -> 12583.422 | I10: Months Remaining | J10: =DATEDIF(NOW(), J9,"M") -> 12
B11: =B10+1 -> 8 | C11: =DATE(YEAR(C10),MONTH(C10)+1,Day(C10)) -> 44518 | D11: -298.96 | E11: =IPMT($J$3/12, B11, $I$5*12,$I$3) -> -172.43225 | F11: =D11-E11 -> -126.52775 | G11: =F11+G10 -> 12456.894 | I11: Months Total | J11: =72 -> 72
B12: =B11+1 -> 9 | C12: =DATE(YEAR(C11),MONTH(C11)+1,Day(C11)) -> 44548 | D12: -298.96 | E12: =IPMT($J$3/12, B12, $I$5*12,$I$3) -> -170.76859 | F12: =D12-E12 -> -128.19141 | G12: =F12+G11 -> 12328.703 | I12: Percent Complete | J12: =1 - (DATEDIF(NOW(), J9,"M") / 72) -> 0.83333333
B13: =B12+1 -> 10 | C13: =DATE(YEAR(C12),MONTH(C12)+1,Day(C12)) -> 44579 | D13: -298.96 | E13: =IPMT($J$3/12, B13, $I$5*12,$I$3) -> -169.08218 | F13: =D13-E13 -> -129.87782 | G13: =F13+G12 -> 12198.825
B14: =B13+1 -> 11 | C14: =DATE(YEAR(C13),MONTH(C13)+1,Day(C13)) -> 44610 | D14: -298.96 | E14: =IPMT($J$3/12, B14, $I$5*12,$I$3) -> -167.37273 | F14: =D14-E14 -> -131.58727 | G14: =F14+G13 -> 12067.238
B15: =B14+1 -> 12 | C15: =DATE(YEAR(C14),MONTH(C14)+1,Day(C14)) -> 44638 | D15: -298.96 | E15: =IPMT($J$3/12, B15, $I$5*12,$I$3) -> -165.63992 | F15: =D15-E15 -> -133.32008 | G15: =F15+G14 -> 11933.918
B16: =B15+1 -> 13 | C16: =DATE(YEAR(C15),MONTH(C15)+1,Day(C15)) -> 44669 | D16: -298.96 | E16: =IPMT($J$3/12, B16, $I$5*12,$I$3) -> -163.88342 | F16: =D16-E16 -> -135.07658 | G16: =F16+G15 -> 11798.841
B17: =B16+1 -> 14 | C17: =DATE(YEAR(C16),MONTH(C16)+1,Day(C16)) -> 44699 | D17: -298.96 | E17: =IPMT($J$3/12, B17, $I$5*12,$I$3) -> -162.10292 | F17: =D17-E17 -> -136.85708 | G17: =F17+G16 -> 11661.984
B18: =B17+1 -> 15 | C18: =DATE(YEAR(C17),MONTH(C17)+1,Day(C17)) -> 44730 | D18: -298.96 | E18: =IPMT($J$3/12, B18, $I$5*12,$I$3) -> -160.29809 | F18: =D18-E18 -> -138.66191 | G18: =F18+G17 -> 11523.322
B19: =B18+1 -> 16 | C19: =DATE(YEAR(C18),MONTH(C18)+1,Day(C18)) -> 44760 | D19: -298.96 | E19: =IPMT($J$3/12, B19, $I$5*12,$I$3) -> -158.46859 | F19: =D19-E19 -> -140.49141 | G19: =F19+G18 -> 11382.831
B20: =B19+1 -> 17 | C20: =DATE(YEAR(C19),MONTH(C19)+1,Day(C19)) -> 44791 | D20: -298.96 | E20: =IPMT($J$3/12, B20, $I$5*12,$I$3) -> -156.61409 | F20: =D20-E20 -> -142.34591 | G20: =F20+G19 -> 11240.485
B21: =B20+1 -> 18 | C21: =DATE(YEAR(C20),MONTH(C20)+1,Day(C20)) -> 44822 | D21: -298.96 | E21: =IPMT($J$3/12, B21, $I$5*12,$I$3) -> -154.73424 | F21: =D21-E21 -> -144.22576 | G21: =F21+G20 -> 11096.259
B22: =B21+1 -> 19 | C22: =DATE(YEAR(C21),MONTH(C21)+1,Day(C21)) -> 44852 | D22: -298.96 | E22: =IPMT($J$3/12, B22, $I$5*12,$I$3) -> -152.8287 | F22: =D22-E22 -> -146.1313 | G22: =F22+G21 -> 10950.128
B23: =B22+1 -> 20 | C23: =DATE(YEAR(C22),MONTH(C22)+1,Day(C22)) -> 44883 | D23: -298.96 | E23: =IPMT($J$3/12, B23, $I$5*12,$I$3) -> -150.89712 | F23: =D23-E23 -> -148.06288 | G23: =F23+G22 -> 10802.065
B24: =B23+1 -> 21 | C24: =DATE(YEAR(C23),MONTH(C23)+1,Day(C23)) -> 44913 | D24: -298.96 | E24: =IPMT($J$3/12, B24, $I$5*12,$I$3) -> -148.93914 | F24: =D24-E24 -> -150.02086 | G24: =F24+G23 -> 10652.044
... B35: =B34+1 -> 32 | C35: =DATE(YEAR(C34),MONTH(C34)+1,Day(C34)) -> 45248 | D35: -298.96 | E35: =IPMT($J$3/12, B35, $I$5*12,$I$3) -> -125.55227 | F35: =D35-E35 -> -173.40773 | G35: =F35+G34 -> 8864.6665
B36: =B35+1 -> 33 | C36: =DATE(YEAR(C35),MONTH(C35)+1,Day(C35)) -> 45278 | D36: -298.96 | E36: =IPMT($J$3/12, B36, $I$5*12,$I$3) -> -123.24791 | F36: =D36-E36 -> -175.71209 | G36: 8906.17
B37: =B36+1 -> 34 | C37: =DATE(YEAR(C36),MONTH(C36)+1,Day(C36)) -> 45309 | D37: -298.96 | E37: =IPMT($J$3/12, B37, $I$5*12,$I$3) -> -120.91206 | F37: =D37-E37 -> -178.04794 | G37: =F37+G36 -> 8728.1221
B38: =B37+1 -> 35 | C38: =DATE(YEAR(C37),MONTH(C37)+1,Day(C37)) -> 45340 | D38: -298.96 | E38: =IPMT($J$3/12, B38, $I$5*12,$I$3) -> -118.54428 | F38: =D38-E38 -> -180.41572 | G38: =F38+G37 -> 8547.7063
B39: =B38+1 -> 36 | C39: =DATE(YEAR(C38),MONTH(C38)+1,Day(C38)) -> 45369 | D39: -298.96 | E39: =IPMT($J$3/12, B39, $I$5*12,$I$3) -> -116.14415 | F39: =D39-E39 -> -182.81585 | G39: =F39+G38 -> 8364.8905
B40: =B39+1 -> 37 | C40: =DATE(YEAR(C39),MONTH(C39)+1,Day(C39)) -> 45400 | D40: -298.96 | E40: =IPMT($J$3/12, B40, $I$5*12,$I$3) -> -113.71121 | F40: =D40-E40 -> -185.24879 | G40: =F40+G39 -> 8179.6417
B41: =B40+1 -> 38 | C41: =DATE(YEAR(C40),MONTH(C40)+1,Day(C40)) -> 45430 | D41: -298.96 | E41: =IPMT($J$3/12, B41, $I$5*12,$I$3) -> -111.24502 | F41: =D41-E41 -> -187.71498 | G41: =F41+G40 -> 7991.9267
B42: =B41+1 -> 39 | C42: =DATE(YEAR(C41),MONTH(C41)+1,Day(C41)) -> 45461 | D42: -298.96 | E42: =IPMT($J$3/12, B42, $I$5*12,$I$3) -> -108.74513 | F42: =D42-E42 -> -190.21487 | G42: =F42+G41 -> 7801.7118
B43: =B42+1 -> 40 | C43: =DATE(YEAR(C42),MONTH(C42)+1,Day(C42)) -> 45491 | D43: -298.96 | E43: =IPMT($J$3/12, B43, $I$5*12,$I$3) -> -106.21107 | F43: =D43-E43 -> -192.74893 | G43: =F43+G42 -> 7608.9629
B44: =B43+1 -> 41 | C44: =DATE(YEAR(C43),MONTH(C43)+1,Day(C43)) -> 45522 | D44: -298.96 | E44: =IPMT($J$3/12, B44, $I$5*12,$I$3) -> -103.64238 | F44: =D44-E44 -> -195.31762 | G44: =F44+G43 -> 7413.6453
B45: =B44+1 -> 42 | C45: =DATE(YEAR(C44),MONTH(C44)+1,Day(C44)) -> 45553 | D45: -298.96 | E45: =IPMT($J$3/12, B45, $I$5*12,$I$3) -> -101.03859 | F45: =D45-E45 -> -197.92141 | G45: =F45+G44 -> 7215.7239
B46: =B45+1 -> 43 | C46: =DATE(YEAR(C45),MONTH(C45)+1,Day(C45)) -> 45583 | D46: -298.96 | E46: =IPMT($J$3/12, B46, $I$5*12,$I$3) -> -98.399207 | F46: =D46-E46 -> -200.56079 | G46: =F46+G45 -> 7015.1631
B47: =B46+1 -> 44 | C47: =DATE(YEAR(C46),MONTH(C46)+1,Day(C46)) -> 45614 | D47: -298.96 | E47: =IPMT($J$3/12, B47, $I$5*12,$I$3) -> -95.723756 | F47: =D47-E47 -> -203.23624 | G47: =F47+G46 -> 6811.9268
B48: =B47+1 -> 45 | C48: =DATE(YEAR(C47),MONTH(C47)+1,Day(C47)) -> 45644 | D48: -298.96 | E48: =IPMT($J$3/12, B48, $I$5*12,$I$3) -> -93.01174 | F48: =D48-E48 -> -205.94826 | G48: =F48+G47 -> 6605.9786
... B75: =B74+1 -> 72 | C75: =DATE(YEAR(C74),MONTH(C74)+1,Day(C74)) -> 46464 | D75: -298.96 | E75: =IPMT($J$3/12, B75, $I$5*12,$I$3) -> -3.9660383 | F75: =D75-E75 -> -294.99396 | G75: =F75+G74 -> -128.09929

Sheet 08) Drop Down Menus
A1: Expence Catagories | B1: Shopping Catagories
A2: Groceries | B2: Groceries | D2: Current Time | E2: Current Date
A3: Cigarettes | B3: Living Room | D3: =TEXT(TIME(VALUE(TEXT(NOW(), "H")), VALUE(TEXT(NOW(), "MM")+25), VALUE(TEXT(NOW(), "SS"))), "H:MM AM/PM") -> 5:28 PM | E3: =TEXT(TODAY(), "MM/DD/YYYY") -> 03/12/2026
A4: Gas | B4: Kitchen
A5: Entertainment | B5: Bathroom
A6: Medical | B6: Bedroom
A7: Vehicle | B7: Entertainment
A8: Maintenance | B8: Cleaning Supplies
A9: Debt | B9: Maintenance
A10: Holiday Gifts | B10: Outdoors
A11: Haircut | B11: Vehicle
A12: Subscription - Video | B12: Groceries (Lunch)
A13: Subscription - Game | B13: Cigarettes
A14: Credit Cards | B14: Medical
B15: Other
B16: Office

Sheet 09) Affirm Payoff Schedule
A1: Affirm Payoff Schedule / Phone Number to Call : 1-855-423-3729
B2: Payment | C2: Date | D2: Amount | E2: Remaining | H2: Payment | I2: Date | J2: Amount | K2: Remaining | N2: Affirm | O2: Loan Code | P2: Total Owed | Q2: Percentage
A3: 44951 | B3: WalMart 1 | C3: 44960 | D3: 47.35 | E3: =P3-D3 -> 1088.99 | G3: 45041 | H3: WalMart 1- | I3: =C28+14 -> 45037 | J3: 47.35 | K3: =E28-J3 -> 946.94 | N3: WalMart 1 | O3: 40M4-D7QC | P3: 1136.34 | Q3: =P3/P8 -> 0.34987776
B4: WalMart 2 | C4: 44960 | D4: 47.06 | E4: =P4-D4 -> 1082.28 | H4: WalMart 2- | I4: =C29+14 -> 45037 | J4: 47.06 | K4: =E29-J4 -> 941.1 | N4: WalMart 2 | O4: 3DXV-RNTY | P4: 1129.34 | Q4: =P4/P8 -> 0.34772247
B5: NewEgg | C5: 44960 | D5: 23.61 | E5: =P5-D5 -> 543.04 | H5: NewEgg- | I5: =C30+14 -> 45037 | J5: 23.61 | K5: =E30-J5 -> 472.21 | N5: NewEgg | O5: 4WY1-RWEJ | P5: 566.65 | Q5: =P5/P8 -> 0.17447088
B6: WalMart 3 | C6: 44960 | D6: 6.3 | E6: =P6-D6 -> 144.97 | H6: WalMart 3- | I6: =C31+14 -> 45037 | J6: 6.3 | K6: =E31-J6 -> 126.07 | N6: WalMart 3 | O6: 4BY2-JGPS | P6: 151.27 | Q6: =P6/P8 -> 0.046575857
B7: WalMart 4 | C7: 44960 | D7: 11.01 | E7: =P7-D7 -> 253.21 | H7: WalMart 4- | I7: =C32+14 -> 45037 | J7: 11.01 | K7: =E32-J7 -> 220.18 | N7: WalMart 4 | O7: QUNW-WR5S | P7: 264.22 | Q7: =P7/P8 -> 0.081353031
A8: 44982 | B8: WalMart 1 | C8: 44967 | D8: 47.35 | E8: =E3-D8 -> 1041.64 | G8: 45071 | H8: WalMart 1- | I8: =I3+14 -> 45051 | J8: 47.35 | K8: =K3-J8 -> 899.59 | N8: Total : | P8: =SUM(P3:P7) -> 3247.82
B9: WalMart 2 | C9: 44967 | D9: 47.06 | E9: =E4-D9 -> 1035.22 | H9: WalMart 2- | I9: =I4+14 -> 45051 | J9: 47.06 | K9: =K4-J9 -> 894.04 | N9: Remaining : | P9: =P8-(P8-sum(P22:P26)) -> 2977.1683
B10: NewEgg | C10: 44967 | D10: 23.61 | E10: =E5-D10 -> 519.43 | H10: NewEgg- | I10: =I5+14 -> 45051 | J10: 23.61 | K10: =K5-J10 -> 448.6 | N10: Paid : | P10: =P8-sum(P22:P26) -> 270.65167
B11: WalMart 3 | C11: 44967 | D11: 6.3 | E11: =E6-D11 -> 138.67 | H11: WalMart 3- | I11: =I6+14 -> 45051 | J11: 6.3 | K11: =K6-J11 -> 119.77
B12: WalMart 4 | C12: 44967 | D12: 11.01 | E12: =E7-D12 -> 242.2 | H12: WalMart 4- | I12: =I7+14 -> 45051 | J12: 11.01 | K12: =K7-J12 -> 209.17 | N12: Per Month | P12: Per Paycheck
A13: Skipped | B13: Skipped | G13: 45102 | H13: WalMart 1- | I13: =I8+14 -> 45065 | J13: 47.35 | K13: =K8-J13 -> 852.24 | N13: =N19*Q3 -> 94.695 | P13: =P19*Q3 -> 47.3475
H14: WalMart 2- | I14: =I9+14 -> 45065 | J14: 47.06 | K14: =K9-J14 -> 846.98 | N14: =N19*Q4 -> 94.111667 | P14: =P19*Q4 -> 47.055833
H15: NewEgg- | I15: =I10+14 -> 45065 | J15: 23.61 | K15: =K10-J15 -> 424.99 | N15: =N19*Q5 -> 47.220833 | P15: =P19*Q5 -> 23.610417
H16: WalMart 3- | I16: =I11+14 -> 45065 | J16: 6.3 | K16: =K11-J16 -> 113.47 | N16: =N19*Q6 -> 12.605833 | P16: =P19*Q6 -> 6.3029167
H17: WalMart 4- | I17: =I12+14 -> 45065 | J17: 11.01 | K17: =K12-J17 -> 198.16 | N17: =N19*Q7 -> 22.018333 | P17: =P19*Q7 -> 11.009167
A18: Skipped | B18: Skipped | G18: 45132 | H18: WalMart 1- | I18: =I13+14 -> 45079 | J18: 47.35 | K18: =K13-J18 -> 804.89 | N18: TOTAL
H19: WalMart 2- | I19: =I14+14 -> 45079 | J19: 47.06 | K19: =K14-J19 -> 799.92 | N19: =P8/12 -> 270.65167 | P19: =N19/2 -> 135.32583
H20: NewEgg- | I20: =I15+14 -> 45079 | J20: 23.61 | K20: =K15-J20 -> 401.38
H21: WalMart 3- | I21: =I16+14 -> 45079 | J21: 6.3 | K21: =K16-J21 -> 107.17 | N21: Paid | P21: Remaining
H22: WalMart 4- | I22: =I17+14 -> 45079 | J22: 11.01 | K22: =K17-J22 -> 187.15 | N22: =countif(B$3:B$66,"WalMart 1") -> 2 | P22: =P3-N22*P13 -> 1041.645
A23: Skipped | B23: Skipped | G23: 45163 | H23: WalMart 1- | I23: =I18+14 -> 45093 | J23: 47.35 | K23: =K18-J23 -> 757.54 | N23: =countif(B$3:B$66,"WalMart 2") -> 2 | P23: =P4-N23*P14 -> 1035.2283
H24: WalMart 2- | I24: =I19+14 -> 45093 | J24: 47.06 | K24: =K19-J24 -> 752.86 | N24: =countif(B$3:B$66,"NewEgg") -> 2 | P24: =P5-N24*P15 -> 519.42917
H25: NewEgg- | I25: =I20+14 -> 45093 | J25: 23.61 | K25: =K20-J25 -> 377.77 | N25: =countif(B$3:B$66,"WalMart 3") -> 2 | P25: =P6-N25*P16 -> 138.66417
H26: WalMart 3- | I26: =I21+14 -> 45093 | J26: 6.3 | K26: =K21-J26 -> 100.87 | N26: =countif(B$3:B$66,"WalMart 4") -> 2 | P26: =P7-N26*P17 -> 242.20167
H27: WalMart 4- | I27: =I22+14 -> 45093 | J27: 11.01 | K27: =K22-J27 -> 176.14 | N27: ="$" & text(sum(P22:P26),"0.00") & " Remaining" -> $2977.17 Remaining
A28: 45010 | B28: WalMart 1- | C28: 45023 | D28: 47.35 | E28: =E8-D28 -> 994.29 | G28: 45194 | H28: WalMart 1- | I28: =I23+14 -> 45107 | J28: 47.35 | K28: =K23-J28 -> 710.19 | N28: Updated : 02/23/2023
B29: WalMart 2- | C29: 45023 | D29: 47.06 | E29: =E9-D29 -> 988.16 | H29: WalMart 2- | I29: =I24+14 -> 45107 | J29: 47.06 | K29: =K24-J29 -> 705.8
B30: NewEgg- | C30: 45023 | D30: 23.61 | E30: =E10-D30 -> 495.82 | H30: NewEgg- | I30: =I25+14 -> 45107 | J30: 23.61 | K30: =K25-J30 -> 354.16
B31: WalMart 3- | C31: 45023 | D31: 6.3 | E31: =E11-D31 -> 132.37 | H31: WalMart 3- | I31: =I26+14 -> 45107 | J31: 6.3 | K31: =K26-J31 -> 94.57
B32: WalMart 4- | C32: 45023 | D32: 11.01 | E32: =E12-D32 -> 231.19 | H32: WalMart 4- | I32: =I27+14 -> 45107 | J32: 11.01 | K32: =K27-J32 -> 165.13
A34: Affirm Payoff Schedule / Phone Number to Call : 1-855-423-3729
B35: Payment | C35: Date | D35: Amount | E35: Remaining | H35: Payment | I35: Date | J35: Amount | K35: Remaining | N35: Payment | O35: Date | P35: Amount | Q35: Remaining
A36: 45224 | B36: WalMart 1- | C36: =I28+14 -> 45121 | D36: 47.35 | E36: =K28-D36 -> 662.84 | G36: 16/25 | H36: WalMart 1- | I36: =C61+14 -> 45205 | J36: 47.35 | K36: =E61-J36 -> 378.74 | M36: 22/25 | N36: WalMart 1- | O36: =I61+14 -> 45289 | P36: =47.29+0.06 -> 47.35 | Q36: =K61-P36 -> 94.7
B37: WalMart 2- | C37: =I29+14 -> 45121 | D37: 47.06 | E37: =K29-D37 -> 658.74 | H37: WalMart 2- | I37: =C62+14 -> 45205 | J37: 47.06 | K37: =E62-J37 -> 376.38 | N37: WalMart 2- | O37: =I62+14 -> 45289 | P37: =46.96+0.1 -> 47.06 | Q37: =K62-P37 -> 94.12
B38: NewEgg- | C38: =I30+14 -> 45121 | D38: 23.61 | E38: =K30-D38 -> 330.55 | H38: NewEgg- | I38: =C63+14 -> 45205 | J38: 23.61 | K38: =E63-J38 -> 188.89 | N38: NewEgg- | O38: =I63+14 -> 45289 | P38: =23.62-0.01 -> 23.61 | Q38: =K63-P38 -> 47.22
B39: WalMart 3- | C39: =I31+14 -> 45121 | D39: 6.3 | E39: =K31-D39 -> 88.27 | H39: WalMart 3- | I39: =C64+14 -> 45205 | J39: 6.3 | K39: =E64-J39 -> 50.47 | N39: WalMart 3- | O39: =I64+14 -> 45289 | P39: =6.37-0.07 -> 6.3 | Q39: =K64-P39 -> 12.6
B40: WalMart 4- | C40: =I32+14 -> 45121 | D40: 11.01 | E40: =K32-D40 -> 154.12 | H40: WalMart 4- | I40: =C65+14 -> 45205 | J40: 11.01 | K40: =E65-J40 -> 88.06 | N40: WalMart 4- | O40: =I65+14 -> 45289 | P40: =10.99+0.02 -> 11.01 | Q40: =K65-P40 -> 22.02
A41: 45255 | B41: WalMart 1- | C41: =C36+14 -> 45135 | D41: 47.35 | E41: =E36-D41 -> 615.49 | G41: 17/25 | H41: WalMart 1- | I41: =I36+14 -> 45219 | J41: 47.35 | K41: =K36-J41 -> 331.39 | M41: 23/25 | N41: WalMart 1- | O41: =O36+14 -> 45303 | P41: =47.29+0.06 -> 47.35 | Q41: =Q36-P41 -> 47.35
...

Sheet 10) 2022 BudgetBill Breakdown
B1: Bills | C1: Pay Date | D1: Minimum Due | E1: Remaining / Notes | F1: Check Balance | G1: Checking Balance
A2: TRUE | B2: Paycheck MTM | C2: 44869 | D2: 1193.12 | F2: =D2 -> 1193.12 | G2: =D2+4.33 -> 1197.45
A3: TRUE | B3: Overtime | C3: 44869 | D3: 78.49 | F3: =D3+F2 -> 1271.61 | G3: =G2+D3 -> 1275.94
A4: TRUE | B4: ='2022 Expences - 11042022'!$I$4 -> Groceries | C4: N/A | D4: =-'2022 Expences - 11042022'!$J$4 -> -218.62 | F4: =D4+F3 -> 1052.99 | G4: =G3+D4 -> 1057.32
A5: TRUE | B5: ='2022 Expences - 11042022'!$I$5 -> Cigarettes | C5: N/A | D5: =-'2022 Expences - 11042022'!$J$5 -> -53.43 | F5: =D5+F4 -> 999.56 | G5: =G4+D5 -> 1003.89
A6: TRUE | B6: ='2022 Expences - 11042022'!$I$6 -> Gas | C6: N/A | D6: =-'2022 Expences - 11042022'!$J$6 -> 0 | F6: =D6+F5 -> 999.56 | G6: =G5+D6 -> 1003.89
A7: TRUE | B7: ='2022 Expences - 11042022'!$I$7 -> Entertainment | C7: N/A | D7: =-'2022 Expences - 11042022'!$J$7 -> -20.49 | F7: =D7+F6 -> 979.07 | G7: =G6+D7 -> 983.4
A8: TRUE | B8: ='2022 Expences - 11042022'!$I$8 -> Medical | C8: N/A | D8: =-'2022 Expences - 11042022'!$J$8 -> -5.25 | F8: =D8+F7 -> 973.82 | G8: =G7+D8 -> 978.15
A9: TRUE | B9: ='08) Drop Down Menus'!A8 -> Maintenance | C9: N/A | D9: =-'2022 Expences - 11042022'!J10 -> -155.7 | F9: =F8+D9 -> 818.12 | G9: =G8+D9 -> 822.45
A10: TRUE | B10: ='2022 Expences - 11042022'!$I$9 -> Vehicle | C10: N/A | D10: =-'2022 Expences - 11042022'!$J$9 -> 0 | F10: =F9+D10 -> 818.12 | G10: =G9+D10 -> 822.45
A11: TRUE | B11: Half Rent | C11: 44869 | D11: =-447.5-34.81 -> -482.31 | E11: Rent - 1st Half December + Water | F11: =D11+F10 -> 335.81 | G11: =G10+D11 -> 340.14
A12: TRUE | B12: Car Insurance | C12: 44869 | D12: -64.71 | F12: =D12+F11 -> 271.1 | G12: =G11+D12 -> 275.43
A13: TRUE | B13: US Cellular - Bill | C13: 44869 | D13: =-92.13-29.11+16.84 -> -104.4 | E13: Early Pay | F13: =F12+D13 -> 166.7 | G13: =G12+D13 -> 171.03
A14: TRUE | B14: US Cellular - Phone | C14: 44869 | D14: -46.66 | E14: Payment 23 / 30 | F14: =F13+D14 -> 120.04 | G14: =G13+D14 -> 124.37
A15: TRUE | B15: Renter's Insurance | C15: 44869 | D15: -11.85 | F15: =F14+D15 -> 108.19 | G15: =G14+D15 -> 112.52
A16: TRUE | B16: Above Lending | C16: 44872 | D16: -86.95 | E16: 6511.74 | F16: =F15+D16 -> 21.24 | G16: =G15+D16 -> 25.57
A17: TRUE | B17: Planet Fitness | C17: 44878 | D17: -10 | F17: =F16+D17 -> 11.24 | G17: =G16+D17 -> 15.57
A18: TRUE | B18: Affirm (Walmart - $1336.14) | C18: 44882 | D18: -58.1 | E18: =1336.14+D18 -> 1278.04 | F18: =F17+D18 -> -46.86 | G18: =G17+D18 -> -42.53
A19: TRUE | B19: Affirm (Walmart - $1328.18) | C19: 44882 | D19: -57.74 | E19: =1328.18+D19 -> 1270.44 | F19: =F18+D19 -> -104.6 | G19: =G18+D19 -> -100.27
A20: TRUE | B20: Affirm (Walmart - $264.22) | C20: 44882 | D20: -29.36 | E20: =264.22+D20 -> 234.86 | F20: =F19+D20 -> -133.96 | G20: =G19+D20 -> -129.63
A21: TRUE | B21: Affirm (Walmart - $151.27) | C21: 44882 | D21: -16.81 | E21: =151.27+D21 -> 134.46 | F21: =F20+D21 -> -150.77 | G21: =G20+D21 -> -146.44
B22: 11/04/2022 - 11/17/2022 | E22: Extra Money Left Over : | F22: =G17 -> 15.57
A23: TRUE | B23: Paycheck MTM | C23: 44883 | D23: 1208.58 | F23: =D23 -> 1208.58 | G23: =D23+F22 -> 1224.15
A24: TRUE | B24: Overtime | C24: 44883 | D24: 0 | F24: =D24+F23 -> 1208.58 | G24: =G23+D24 -> 1224.15
A25: TRUE | B25: ='2022 Expences - 11182022'!$I$4 -> Groceries | C25: N/A | D25: =-'2022 Expences - 11182022'!$J$4 -> -106.91 | F25: =D25+F24 -> 1101.67 | G25: =G24+D25 -> 1117.24
A26: TRUE | B26: ='2022 Expences - 11182022'!$I$5 -> Cigarettes | C26: N/A | D26: =-'2022 Expences - 11182022'!$J$5 -> -77.19 | F26: =D26+F25 -> 1024.48 | G26: =G25+D26 -> 1040.05
A27: TRUE | B27: ='2022 Expences - 11182022'!$I$6 -> Gas | C27: N/A | D27: =-'2022 Expences - 11182022'!$J$6 -> -32.8 | F27: =D27+F26 -> 991.68 | G27: =G26+D27 -> 1007.25
A28: TRUE | B28: ='2022 Expences - 11182022'!$I$7 -> Entertainment | C28: N/A | D28: =-'2022 Expences - 11182022'!$J$7 -> -7.24 | F28: =D28+F27 -> 984.44 | G28: =G27+D28 -> 1000.01
A29: TRUE | B29: ='2022 Expences - 11182022'!$I$8 -> Medical | C29: N/A | D29: =-'2022 Expences - 11182022'!$J$8 -> -30 | F29: =D29+F28 -> 954.44 | G29: =G28+D29 -> 970.01
A30: TRUE | B30: ='08) Drop Down Menus'!A8 -> Maintenance | C30: N/A | D30: =-'2022 Expences - 11182022'!J10 -> -23.43 | F30: =D30+F29 -> 931.01 | G30: =G29+D30 -> 946.58
A31: TRUE | B31: ='2022 Expences - 11182022'!$I$9 -> Vehicle | C31: N/A | D31: =-'2022 Expences - 11182022'!$J$9 -> 0 | F31: =D31+F30 -> 931.01 | G31: =G30+D31 -> 946.58
A32: TRUE | B32: Half Rent | C32: 44883 | D32: =-447.5 -> -447.5 | E32: Rent - 2nd Half December | F32: =D32+F31 -> 483.51 | G32: =G31+D32 -> 499.08
A33: TRUE | B33: Car Payment | C33: 44883 | D33: =-315-4.95 -> -319.95 | E33: November Car Payment | F33: =D33+F32 -> 163.56 | G33: =G32+D33 -> 179.13
A34: TRUE | B34: Above Lending | C34: 44886 | D34: -86.95 | E34: 0 | F34: =D34+F33 -> 76.61 | G34: =G33+D34 -> 92.18
A35: TRUE | B35: Credit Cards | C35: 44883 | D35: -29 | F35: =D35+F34 -> 47.61 | G35: =G34+D35 -> 63.18
A36: TRUE | B36: WPS - Gas | C36: 44883 | D36: -62 | F36: =D36+F35 -> -14.39 | G36: =G35+D36 -> 1.18
A37: TRUE | B37: Affirm (NewEgg - $566.65) | C37: 44883 | D37: 0 | E37: 113.34 | F37: =D37+F36 -> -14.39 | G37: =G36+D37 -> 1.18
B38: 11/18/2022 - 12/01/2022 | E38: Extra Money Left Over : | F38: $ 0.18
A39: TRUE | B39: Paycheck MTM | C39: 44897 | D39: =1166.82-D40 -> 1020.84 | F39: =D39 -> 1020.84 | G39: =D39+F38 -> 1021.02
A40: TRUE | B40: Overtime | C40: 44897 | D40: 145.98 | F40: =D40+F39 -> 1166.82 | G40: =G39+D40 -> 1167
...

Sheet 11) 2023 BudgetBill Breakdown
B1: Bill | C1: Description | D1: Withdrawl Date | E1: Withdrawl Date | F1: Minimum Due | G1: Check Balance | H1: Checking Balance
B2: Income: Paycheck | C2: RECIEVED | D2: 44939 | E2: 44939 | F2: 1052.15 | G2: =F2 -> 1052.15 | H2: ='10) 2022 BudgetBill Breakdown'!F89+G2 -> 1134.59
B3: Groceries | F3: =-'2023 Expences - 01132023'!$J$4 -> -27.14 | G3: =G2+F3 -> 1025.01 | H3: =H2+F3 -> 1107.45
B4: Cigarettes | F4: =-'2023 Expences - 01132023'!$J$5 -> -23.15 | G4: =G3+F4 -> 1001.86 | H4: =H3+F4 -> 1084.3
B5: Gas | F5: =-'2023 Expences - 01132023'!$J$6 -> 0 | G5: =G4+F5 -> 1001.86 | H5: =H4+F5 -> 1084.3
B6: Entertainment | F6: =-'2023 Expences - 01132023'!$J$7 -> -5.76 | G6: =G5+F6 -> 996.1 | H6: =H5+F6 -> 1078.54
B7: Medical | C7: Vyvanse / Prozasin Refills | F7: =-'2023 Expences - 01132023'!$J$8 -> 0 | G7: =G6+F7 -> 996.1 | H7: =H6+F7 -> 1078.54
B8: Vehicle | C8: Oil Change | F8: =-'2023 Expences - 01132023'!$J$9 -> -216.68 | G8: =G7+F8 -> 779.42 | H8: =H7+F8 -> 861.86
B9: Maintenance | C9: Phone Screen Repair | F9: =-'2023 Expences - 01132023'!$J$10 -> -26.26 | G9: =G8+F9 -> 753.16 | H9: =H8+F9 -> 835.6
B10: Above Lending | D10: 44943 | E10: 44943 | F10: -86.96 | G10: =G9+F10 -> 666.2 | H10: =H9+F10 -> 748.64
B11: Planet Fitness | D11: 44943 | E11: 44943 | F11: -10 | G11: =G10+F11 -> 656.2 | H11: =H10+F11 -> 738.64
B12: Car Payment | C12: Half January Payment | D12: 44943 | E12: 44943 | F12: =-315/2 -> -157.5 | G12: =G11+F12 -> 498.7 | H12: =H11+F12 -> 581.14
B13: WPS (Gas Bill) | D13: 44943 | E13: 44943 | F13: -62 | G13: =G12+F13 -> 436.7 | H13: =H12+F13 -> 519.14
B14: US Cellular | C14: Half January Payment | D14: 44940 | E14: 44940 | F14: =-161.57/2 -> -80.785 | G14: =G13+F14 -> 355.915 | H14: =H13+F14 -> 438.355
B15: Credit Cards | D15: 44943 | E15: 44943 | F15: -30 | G15: =G14+F15 -> 325.915 | H15: =H14+F15 -> 408.355
B16: 1/13/2023 - 1/26/2023 | C16: Extra Money Left Over : | H16: =H15+F16 -> 408.355
B17: Income: Paycheck | C17: RECIEVED | D17: =D2+14 -> 44953 | E17: =E2+14 -> 44953 | F17: 1305.26 | G17: =F17 -> 1305.26 | H17: 1456.93
B18: Tax Return (State) | C18: State Tax Return | D18: =D2+21 -> 44960 | E18: =E2+21 -> 44960 | F18: 504 | G18: =G17+F18 -> 1809.26 | H18: =H17+F18 -> 1960.93
B19: Groceries | F19: =-'2023 Expences - 01272023'!$K$3 -> -179.3 | G19: =G18+F19 -> 1629.96 | H19: =H18+F19 -> 1781.63
B20: Cigarettes | F20: =-'2023 Expences - 01272023'!$K$4 -> -29.38 | G20: =G19+F20 -> 1600.58 | H20: =H19+F20 -> 1752.25
B21: Gas | F21: =-'2023 Expences - 01272023'!$K$5 -> -67.87 | G21: =G20+F21 -> 1532.71 | H21: =H20+F21 -> 1684.38
B22: Entertainment | F22: =-'2023 Expences - 01272023'!$K$6 -> -10.49 | G22: =G21+F22 -> 1522.22 | H22: =H21+F22 -> 1673.89
B23: Medical | F23: =-'2023 Expences - 01272023'!$K$7 -> 0 | G23: =G22+F23 -> 1522.22 | H23: =H22+F23 -> 1673.89
B24: Vehicle | F24: =-'2023 Expences - 01272023'!$K$8 -> -12 | G24: =G23+F24 -> 1510.22 | H24: =H23+F24 -> 1661.89
B25: Maintenance | F25: =-'2023 Expences - 01272023'!$K$9 -> 0 | G25: =G24+F25 -> 1510.22 | H25: =H24+F25 -> 1661.89
B26: Debt | C26: Affirm Payments | F26: =-'2023 Expences - 01272023'!$K$10 -> -135.35 | G26: =G25+F26 -> 1374.87 | H26: =H25+F26 -> 1526.54
B27: Rent | D27: 44953 | E27: 44953 | F27: -923.1 | G27: =G26+F27 -> 451.77 | H27: =H26+F27 -> 603.44
B28: Car Payment | C28: 2nd Half January Payment | D28: 44954 | E28: 44954 | F28: =-315/2 -> -157.5 | G28: =G27+F28 -> 294.27 | H28: =H27+F28 -> 445.94
B29: XFinity | D29: 44954 | E29: 44954 | F29: -75.75 | G29: =G28+F29 -> 218.52 | H29: =H28+F29 -> 370.19
B30: US Cellular | C30: 2nd Half January Payment | D30: 44954 | E30: 44954 | F30: -67.44 | G30: =G29+F30 -> 151.08 | H30: =H29+F30 -> 302.75
B31: Car Insurance | D31: 44954 | E31: 44954 | F31: -60.95 | G31: =G30+F31 -> 90.13 | H31: =H30+F31 -> 241.8
B32: Renter's Insurance | D32: 44954 | E32: 44954 | F32: -13.65 | G32: =G31+F32 -> 76.48 | H32: =H31+F32 -> 228.15
B33: Above Lending | D33: 44956 | E33: 44956 | F33: -86.95 | G33: =G32+F33 -> -10.47 | H33: =H32+F33 -> 141.2
B34: Subscription - Video | C34: (Includes HIDive Sub) | D34: 44957 | E34: 44957 | F34: -20.28 | G34: =G33+F34 -> -30.75 | H34: =H33+F34 -> 120.92
B35: Subscription - Game | D35: 44963 | E35: 44963 | F35: -14.99 | G35: =G34+F35 -> -45.74 | H35: =H34+F35 -> 105.93
B36: 1/27/2023 - 2/09/2023 | C36: Extra Money Left Over : | H36: =H35 -> 105.93
B37: Income: Paycheck | C37: RECIEVED | D37: =D17+14 -> 44967 | E37: =E17+14 -> 44967 | F37: 1477.33 | G37: =F37 -> 1477.33 | H37: 1583.08
B38: Groceries | F38: =-'2023 Expences - 02102023'!$K$3 -> -232.71 | G38: =G37+F38 -> 1244.62 | H38: =H37+F38 -> 1350.37
B39: Cigarettes | F39: =-'2023 Expences - 02102023'!$K$4 -> -46.81 | G39: =G38+F39 -> 1197.81 | H39: =H38+F39 -> 1303.56
B40: Gas | F40: =-'2023 Expences - 02102023'!$K$5 -> 0 | G40: =G39+F40 -> 1197.81 | H40: =H39+F40 -> 1303.56
...

Sheet 11) 2023 YTD Report
J1: DROPDOWN
B2: Income | C2: 2023 YTD Amount | G2: US Cellular | H2: =-I$2/C$33 -> 0.059075708 | I2: =SUMIF('11) 2023 BudgetBill Breakdown'!B$1:B37,J$5, '11) 2023 BudgetBill Breakdown'!F$1:F37) -> -2092.715 | J2: Income: Paycheck
B3: Income: Paycheck | C3: =SUMIF('11) 2023 BudgetBill Breakdown'!B1:B37,B3, '11) 2023 BudgetBill Breakdown'!F1:F37) -> 33987.69 | G3: =J$6 -> Rent | H3: =-I$3/C$33 -> 0.31436989 | I3: =SUMIF('11) 2023 BudgetBill Breakdown'!B$1:B37,"Rent", '11) 2023 BudgetBill Breakdown'!F$1:F37) -> -11136.33 | J3: Tax Return (State)
B4: Tax Return (State) | C4: =SUMIF('11) 2023 BudgetBill Breakdown'!B$1:B37,B4, '11) 2023 BudgetBill Breakdown'!F$1:F37) -> 504 | G4: ='08) Drop Down Menus'!$A$2 -> Groceries | H4: =-I$4/C$33 -> 0.14468208 | I4: =SUMIF('11) 2023 BudgetBill Breakdown'!B$1:B37,J$7, '11) 2023 BudgetBill Breakdown'!F$1:F37) -> -5125.26 | J4: Beyond Finance Return
B5: Beyond Finance Return | C5: =SUMIF('11) 2023 BudgetBill Breakdown'!B$1:B37,B5, '11) 2023 BudgetBill Breakdown'!F$1:F37) -> 932.6 | G5: ='08) Drop Down Menus'!$A$3 -> Cigarettes | H5: =-I$5/C$33 -> 0.036822192 | I5: =SUMIF('11) 2023 BudgetBill Breakdown'!B$1:B37,J$8, '11) 2023 BudgetBill Breakdown'!F$1:F37) -> -1304.4 | J5: US Cellular
G6: ='08) Drop Down Menus'!$A$4 -> Gas | H6: =-I$6/C$33 -> 0.014090614 | I6: =SUMIF('11) 2023 BudgetBill Breakdown'!B$1:B37,J$9, '11) 2023 BudgetBill Breakdown'!F$1:F37) -> -499.15 | J6: Rent
B7: Expence | C7: YTD Cost | D7: Percentile | E7: Monthly Avg. | G7: ='08) Drop Down Menus'!$A$5 -> Entertainment | H7: =-I$7/C$33 -> 0.024633945 | I7: =SUMIF('11) 2023 BudgetBill Breakdown'!B$1:B37,J$10, '11) 2023 BudgetBill Breakdown'!F$1:F37) -> -872.64 | J7: Groceries
B8: =G$3 -> Rent | C8: =I$3 -> -11136.33 | D8: =H$3 -> 0.31436989 | E8: =C8/H$26 -> -3287.8689 | G8: ='08) Drop Down Menus'!$A$6 -> Medical | H8: =-I$8/C$33 -> 0.020695404 | I8: =SUMIF('11) 2023 BudgetBill Breakdown'!B$1:B37,J$11, '11) 2023 BudgetBill Breakdown'!F$1:F37) -> -733.12 | J8: Cigarettes
B9: =G$4 -> Groceries | C9: =I$4 -> -5125.26 | D9: =H$4 -> 0.14468208 | E9: =C9/H$26 -> -1513.172 | G9: ='08) Drop Down Menus'!$A$7 -> Vehicle | H9: =-I$9/C$33 -> 0.014015807 | I9: =SUMIF('11) 2023 BudgetBill Breakdown'!B$1:B37,J$12, '11) 2023 BudgetBill Breakdown'!F$1:F37) -> -496.5 | J9: Gas
B10: =G$13 -> Car Payment | C10: =I$13 -> -3613.46 | D10: =H$13 -> 0.10200515 | E10: =C10/H$26 -> -1066.831 | G10: ='08) Drop Down Menus'!$A$8 -> Maintenance | H10: =-I$10/C$33 -> 0.028747789 | I10: =SUMIF('11) 2023 BudgetBill Breakdown'!B$1:B37,J$13, '11) 2023 BudgetBill Breakdown'!F$1:F37) -> -1018.37 | J10: Entertainment
B11: =G$11 -> Above Lending | C11: =I$11 -> -2262.41 | D11: =H$11 -> 0.063866065 | E11: =C11/H$26 -> -667.94962 | G11: Above Lending | H11: =-I$11/C$33 -> 0.063866065 | I11: =SUMIF('11) 2023 BudgetBill Breakdown'!B$1:B37,J$14, '11) 2023 BudgetBill Breakdown'!F$1:F37) -> -2262.41 | J11: Medical
B12: =G$2 -> US Cellular | C12: =I$2 -> -2092.715 | D12: =H$2 -> 0.059075708 | E12: =C12/H$26 -> -617.84919 | G12: Planet Fitness | H12: =-I$12/C$33 -> 0.0035026814 | I12: =SUMIF('11) 2023 BudgetBill Breakdown'!B$1:B37,J$15, '11) 2023 BudgetBill Breakdown'!F$1:F37) -> -124.08 | J12: Vehicle
B13: =G$5 -> Cigarettes | C13: =I$5 -> -1304.4 | D13: =H$5 -> 0.036822192 | E13: =C13/H$26 -> -385.10857 | G13: Car Payment | H13: =-I$13/C$33 -> 0.10200515 | I13: =SUMIF('11) 2023 BudgetBill Breakdown'!B$1:B37,J$16, '11) 2023 BudgetBill Breakdown'!F$1:F37) -> -3613.46 | J13: Maintenance
B14: =G$10 -> Maintenance | C14: =I$10 -> -1018.37 | D14: =H$10 -> 0.028747789 | E14: =C14/H$26 -> -300.66162 | G14: WPS (Gas Bill) | H14: =-I$14/C$33 -> 0.022413999 | I14: =SUMIF('11) 2023 BudgetBill Breakdown'!B$1:B37,J$17, '11) 2023 BudgetBill Breakdown'!F$1:F37) -> -794 | J14: Above Lending
B15: =G$21 -> MPU (Electric Bill) | C15: =I$21 -> -968.24 | D15: =H$21 -> 0.027332658 | E15: =C15/H$26 -> -285.86133 | G15: Credit Cards | H15: =-I$15/C$33 -> 0.018444971 | I15: =SUMIF('11) 2023 BudgetBill Breakdown'!B$1:B37,J$18, '11) 2023 BudgetBill Breakdown'!F$1:F37) -> -653.4 | J15: Planet Fitness
B16: =G$16 -> XFinity | C16: =I$16 -> -958.04 | D16: =H$16 -> 0.02704472 | E16: =C16/H$26 -> -282.8499 | G16: XFinity | H16: =-I$16/C$33 -> 0.02704472 | I16: =SUMIF('11) 2023 BudgetBill Breakdown'!B$1:B37,J$19, '11) 2023 BudgetBill Breakdown'!F$1:F37) -> -958.04 | J16: Car Payment
B17: =G$7 -> Entertainment | C17: =I$7 -> -872.64 | D17: =H$7 -> 0.024633945 | E17: =C17/H$26 -> -257.63657 | G17: Car Insurance | H17: =-I$17/C$33 -> 0.022695444 | I17: =SUMIF('11) 2023 BudgetBill Breakdown'!B$1:B37,J$20, '11) 2023 BudgetBill Breakdown'!F$1:F37) -> -803.97 | J17: WPS (Gas Bill)
B18: =G$17 -> Car Insurance | C18: =I$17 -> -803.97 | D18: =H$17 -> 0.022695444 | E18: =C18/H$26 -> -237.36257 | G18: Renter's Insurance | H18: =-I$18/C$33 -> 0.0044209778 | I18: =SUMIF('11) 2023 BudgetBill Breakdown'!B$1:B37,J$21, '11) 2023 BudgetBill Breakdown'!F$1:F37) -> -156.61 | J18: Credit Cards
B19: =G$14 -> WPS (Gas Bill) | C19: =I$14 -> -794 | D19: =H$14 -> 0.022413999 | E19: =C19/H$26 -> -234.41905 | G19: Subscription - Video | H19: =-I$19/C$33 -> 0.0037242807 | I19: =SUMIF('11) 2023 BudgetBill Breakdown'!B$1:B37,J$22, '11) 2023 BudgetBill Breakdown'!F$1:F37) -> -131.93 | J19: XFinity
B20: =G$8 -> Medical | C20: =I$8 -> -733.12 | D20: =H$8 -> 0.020695404 | E20: =C20/H$26 -> -216.44495 | G20: Subscription - Game | H20: =-I$20/C$33 -> 0.0035393793 | I20: =SUMIF('11) 2023 BudgetBill Breakdown'!B$1:B37,J$23, '11) 2023 BudgetBill Breakdown'!F$1:F37) -> -125.38 | J20: Car Insurance
B21: =G$22 -> Debt | C21: =I$22 -> -673.69 | D21: =H$22 -> 0.019017742 | E21: =C21/H$26 -> -198.89895 | G21: MPU (Electric Bill) | H21: =-I$21/C$33 -> 0.027332658 | I21: =SUMIF('11) 2023 BudgetBill Breakdown'!B$1:B37,J$24, '11) 2023 BudgetBill Breakdown'!F$1:F37) -> -968.24 | J21: Renter's Insurance
B22: =G$15 -> Credit Cards | C22: =I$15 -> -653.4 | D22: =H$15 -> 0.018444971 | E22: =C22/H$26 -> -192.90857 | G22: Debt | H22: =-I$22/C$33 -> 0.019017742 | I22: =SUMIF('11) 2023 BudgetBill Breakdown'!B$1:B37,J$25, '11) 2023 BudgetBill Breakdown'!F$1:F37) -> -673.69 | J22: Subscription - Video
